<?xml version="1.0"?>
<robot name="myfirst">

  <material name="blue">
    <color rgba="0 0 0.8 1"/>
  </material>

  <material name="white">
    <color rgba="1 1 1 1"/>
  </material>

  <link name="base_link">
    <visual>
      <geometry>
        <box size="1 1 0.1" />
      </geometry>
      <material name="blue"/>
    </visual>
  </link>
  <link name="cylinder1">
    <visual>
      <geometry>
        <cylinder length="0.6" radius="0.2"/>
      </geometry>
      <material name="blue"/>
    </visual>
  </link>
  <link name="shoulder">
		<visual>
			<geometry>
				<box size="1 0.2 0.2" />
			</geometry>
			<origin rpy="0 0.8 0" xyz="-0.32 0 0.3"/>
			<material name="white"/>
		</visual>
	</link>	
	 <link name="elbow">
		<visual>
			<geometry>
				<box size="0.7 0.18 0.18" />
			</geometry>
			<origin rpy="0 0 0" xyz="-0.25 0 0"/>
		</visual>
	</link>
	  <joint name="base_to_cylinder" type="revolute">
   	 <axis xyz="0 0 1"/>
   	 <limit effort="1000.0" lower="0" upper="3" velocity="0.5"/>
    <parent link="base_link"/>
    <child link="cylinder1"/>
    <origin xyz="0 0 0.3"/>
  </joint>	
   <joint name="cylinder_to_shoulder" type="revolute">
   	 <axis xyz="0 1 0"/>
   	 <limit effort="1000.0" lower="-0.5" upper="0.5" velocity="0.5"/>
    <parent link="cylinder1"/>
    <child link="shoulder"/>
    <origin xyz="0 0 0.3"/>
  </joint>
  <joint name="shoulder_to_elbow" type="revolute">
  	 <axis xyz="0 1 0"/>
   	 <limit effort="1000.0" lower="-0.8" upper="0.8" velocity="0.5"/>
    <parent link="shoulder"/>
    <child link="elbow"/>
    <origin xyz="-0.6 0 0.6"/>
  </joint>
</robot>